tryCatch({
    foo::bar()
}, error = function(e) {
    print("caught the error!")
})
